Workbook
Name Architecture___Design: Lists!$B$2:$B$32
Name CategoryList: Lists!$A$2:$A$8
Name CI: Lists!$G$2:$G$3
Name Data_Science: Lists!$D$2:$D$24
Name Engineering___Quality: Lists!$C$2:$C$82
Name MI: Lists!$H$2:$H$13
Name Professional_Services___Advisory: Lists!$F$2:$F$6
Name Program___Project_Management: Lists!$E$2:$E$20
Name VerticalList: Lists!$J$2:$J$8

Sheet Read Me
B2: Rate Card & Margin Calculator — Tool Overview
B3: ✅ Rates Updated — Master File – Rate Card reflects the latest approved billing rates.
B5: About each sheet
B6: Margin_Summary | C6: Combines Onshore + Offshore outputs to show Total Cost, Total Revenue, and CM% by stream.It will also provide a warning if PM efforts were not taken. Also runs 2 what-if simulations at target CM levels.
B7: Governance | C7: Stores the approval matrix and 3 configurable threshold cells (low/high revenue, CM%). Update these values and the entire approval logic refreshes automatically. No formula editing required.
B8: Revenue & Cost Calculator (Onshore) | C8: Build your onshore team: select role → category auto-fills, headcount, months, and billability. Total cost and revenue calculate automatically per resource and in aggregate.
B9: Revenue & Cost Calculator (Offshore) | C9: Same as Onshore but for offshore resources. Pulls rates in USD from the Master File. Feeds directly into the Margin Simulator.
B10: Master File – Rate Card | C10: Central rate library with 160+ roles (onshore & offshore). Contains cost per hour, annual CTC, and billing rates.
B11: Vertical-Based GM Calculation | C11: Select a Project Vertical (TMT / RAI / RCM / HLS–CI / ME / Others / HLS–Analytics) and Gross Margin % auto-derives from the reference conversion table. Works for Total, Offshore, and Onshore GM separately.
B12: List | C12: his sheet contains the filtered list of records used as the reference dataset for performing VLOOKUP operations and mapping relevant values.
B16: Quick-Start Steps
B17: Step 1 — Set project name and Verticle | C17: Type the project name in Margin Simulator cell C3 and Project verticle in C4. It syncs automatically to both calculator sheets.
B18: Step 2 — Build Onshore team | C18: Go to Revenue & Cost_Onshore. Select Category → Role for each resource. Enter headcount, months, billability.
B19: Step 3 — Build Offshore team | C19: Go to Revenue & Cost_Offshore. Same process as Onshore.
B20: Step 4 — Review Simulator | C20: Open Margin Simulator. Total Cost, Revenue, and CM% are populated automatically.
B21: Step 5 — Select Vertical | C21: Choose the Project Vertical from the C4 dropdown. Offshore GM, Onshore GM, and Total GM populate instantly.
B22: Step 6 — Check Approvals | C22: The Required Approval Authority in row 9 updates based on the calculated revenue and CM%.
B23: Step 7 — Run Simulations | C23: Adjust the yellow Target CM% cells in rows 13–15 to test different margin scenarios.

Sheet Margin_Summary
B2: 💰 Margin CALCULATOR FY25-26
B3: Project Name: | C3: Abc
B4: Project Vertical: | C4: RCM | D4: ← Select Vertical to auto-populate Gross Margin (GM)
C5: Total Cost | D5: Total Revenue | E5: CM (%) | F5: Projected GM (%)
B6: Onshore | C6: ='Revenue & Cost_Onshore'!L29 -> 3386.875 | D6: ='Revenue & Cost_Onshore'!M29 -> 6773.75 | E6: =(D6-C6)/D6 -> 0.5 | F6: =IFERROR(IF(C4="","",E6*INDEX('Vertical-Based GM Calculation'!$O$2:$O$8,MATCH(C4,'Vertical-Based GM Calculation'!$A$2:$A$8,0))),"N/A") -> 0.35246101
B7: Offshore | C7: ='Revenue & Cost_Offshore '!L29 -> 1164.8746 | D7: ='Revenue & Cost_Offshore '!M29 -> 2329.7491 | E7: =(D7-C7)/D7 -> 0.5 | F7: =IFERROR(IF(C4="","",E7*INDEX('Vertical-Based GM Calculation'!$N$2:$N$8,MATCH(C4,'Vertical-Based GM Calculation'!$A$2:$A$8,0))),"N/A") -> 0.39840695
B8: Bench loading rate (Default 5%. Adjustable between 5%-10%) | C8: =$H$8*(C6+C7) -> 227.58748 | G8: Bench %: | H8: 0.05
B9: IP_Product Cost | C9: ='IP_Product Cost'!G15 -> 0 | D9: ='IP_Product Cost'!G16 -> 0
B10: Total | C10: =SUM(C6:C9) -> 4779.337 | D10: =SUM(D6:D9) -> 9103.4991 | E10: =IFERROR((D10-C10)/D10,"-") -> 0.475 | F10: =IFERROR(IF(C4="","",E10*INDEX('Vertical-Based GM Calculation'!$M$2:$M$8,MATCH(C4,'Vertical-Based GM Calculation'!$A$2:$A$8,0))),"N/A") -> 0.37247227
B12: ⚠️ Program Management (PM) Check
B13: Total FTEs (Onshore+Offshore) | C13: PM Role Detected? | D13: Warning
B14: ='Revenue & Cost_Onshore'!F31+'Revenue & Cost_Offshore '!G31 -> 2 | C14: =IF(COUNTIF('Revenue & Cost_Onshore'!D9:D28,"*Manager*")+COUNTIF('Revenue & Cost_Onshore'!D9:D28,"*Scrum*")+COUNTIF('Revenue & Cost_Offshore '!D9:D28,"*Manager*")+COUNTIF('Revenue & Cost_Offshore '!D9:D28,"*Scrum*")>0,"✅ YES","❌ NO") -> ❌ NO | D14: =IFERROR(IF(AND(B14>4,C14="❌ NO"),"⚠️ Project Manager effort not included. Recommended review — ensure adequate Program Management effort is included for this engagement (>4 FTEs detected).",IF(B14>4,"✅ PM effort included. No action needed.","ℹ️ Small team (<5 FTEs) — PM review optional.")), "ℹ️ Configure resources to enable PM check.") -> ℹ️ Small team (<5 FTEs) — PM review optional.
B16: IMP - Margin Simulations - Change CM to view Projected Revenue & GM - Cost does not change
C17: Implied Cost | D17: Projected Revenue | E17: Target CM (%) | F17: Projected GM (%)
B18: Simulation 1 | C18: =$C$10 -> 4779.337 | D18: =IFERROR(C18/(1-E18),"-") -> 9558.6741 | E18: 0.5 | F18: =IFERROR(IF(C4="","",E18*IFERROR(INDEX('Vertical-Based GM Calculation'!$C$15:$C$21,MATCH(C4,'Vertical-Based GM Calculation'!$A$15:$A$21,0)),"")),"")
B19: Simulation 2 | C19: =$C$10 -> 4779.337 | D19: =IFERROR(C19/(1-E19),"-") -> 477933.7 | E19: 0.99 | F19: =IFERROR(IF(C4="","",E19*IFERROR(INDEX('Vertical-Based GM Calculation'!$C$15:$C$21,MATCH(C4,'Vertical-Based GM Calculation'!$A$15:$A$21,0)),"")),"")
B21: 🔵 Blue = User Input | C21: ⚫ Black = Auto-Calculated | D21: 🟡 Yellow = Key Assumption | E21: 🟢 Green = Cross-Sheet Ref

Sheet Governance
B2: 📋 Revenue-Based Approval & Governance Matrix
B4: 📄 Deal Approval Matrix
B5: Deal Value / Revenue | C5: GM Condition | D5: Required Approval Authority
B6: < $250,000 | C6: Any GM | D6: Delivery Lead / Practice Lead + Sales Lead
B7: $250,000 – $1,000,000 | C7: GM ≥ 50% | D7: Delivery Lead / Practice Lead + BU Head + Sales Lead
B8: $250,000 – $1,000,000 | C8: GM < 50% | D8: Delivery Lead / Practice Lead + BU Head + Sales Lead + Leadership Review
B9: > $1,000,000 | C9: Any GM | D9: Delivery Lead / Practice Lead + BU Head + Sales Lead + Leadership Approval
B11: Configurable Thresholds
B12: Parameter | C12: Value
B13: Low Revenue Threshold ($) | C13: 250000
B14: High Revenue Threshold ($) | C14: 1000000
B15: GM Threshold (e.g. 0.5 = 50%) | C15: 0.5

Sheet Revenue & Cost_Onshore
B2: 💰 Onshore REVENUE & COST CALCULATOR
B4: Project Name: | E4: =Margin_Summary!C3 -> Abc | N4: Hours/Month: | O4: 160
B5: Onshore CM%: | E5: 0.5
B6: Expected GM%: | E6: =IFERROR(IF(Margin_Summary!C4="","",E5*INDEX('Vertical-Based GM Calculation'!$O$2:$O$8,MATCH(Margin_Summary!C4,'Vertical-Based GM Calculation'!$A$2:$A$8,0))),"N/A") -> 0.35246101 | F6: ←Do not change this
B8: # | C8: Category | D8: Role | E8: Experience | F8: # People | G8: # Months | H8: Billability % | I8: Cost $/Hr | J8: Annual CTC ($) | K8: Rate per hour ($) | L8: Total Cost (USD) | M8: Total Revenue (USD) | N8: Notes
B9: 1 | C9: Engineering & Quality | D9: Data Engineer / Data Modeler 1 | 2-3 Years | E9: =IF(D9="","",TRIM(MID(D9,FIND("|",D9)+1,100))) -> 2-3 Years | F9: 1 | G9: 1 | H9: 0.5 | I9: =IFERROR(VLOOKUP(D9,'Master File - Rate Card'!$B$4:$H$163,6,0),0) -> 42.335938 | J9: =IFERROR(VLOOKUP(D9,'Master File - Rate Card'!$B$4:$H$163,5,0),0) -> 81285 | K9: =IFERROR(I9/(1-$E$5), 0) -> 84.671875 | L9: =F9*G9*$O$4*H9*I9 -> 3386.875 | M9: =L9/(1-$E$5) -> 6773.75
B10: 2 | E10: =IF(D10="","",TRIM(MID(D10,FIND("|",D10)+1,100))) | I10: =IFERROR(VLOOKUP(D10,'Master File - Rate Card'!$B$4:$H$163,6,0),0) -> 0 | J10: =IFERROR(VLOOKUP(D10,'Master File - Rate Card'!$B$4:$H$163,5,0),0) -> 0 | K10: =IFERROR(I10/(1-$E$5), 0) -> 0 | L10: =F10*G10*$O$4*H10*I10 -> 0 | M10: =L10/(1-$E$5) -> 0
B11: 3 | E11: =IF(D11="","",TRIM(MID(D11,FIND("|",D11)+1,100))) | I11: =IFERROR(VLOOKUP(D11,'Master File - Rate Card'!$B$4:$H$163,6,0),0) -> 0 | J11: =IFERROR(VLOOKUP(D11,'Master File - Rate Card'!$B$4:$H$163,5,0),0) -> 0 | K11: =IFERROR(I11/(1-$E$5), 0) -> 0 | L11: =F11*G11*$O$4*H11*I11 -> 0 | M11: =L11/(1-$E$5) -> 0
B12: 4 | E12: =IF(D12="","",TRIM(MID(D12,FIND("|",D12)+1,100))) | I12: =IFERROR(VLOOKUP(D12,'Master File - Rate Card'!$B$4:$H$163,6,0),0) -> 0 | J12: =IFERROR(VLOOKUP(D12,'Master File - Rate Card'!$B$4:$H$163,5,0),0) -> 0 | K12: =IFERROR(I12/(1-$E$5), 0) -> 0 | L12: =F12*G12*$O$4*H12*I12 -> 0 | M12: =L12/(1-$E$5) -> 0
B13: 5 | E13: =IF(D13="","",TRIM(MID(D13,FIND("|",D13)+1,100))) | I13: =IFERROR(VLOOKUP(D13,'Master File - Rate Card'!$B$4:$H$163,6,0),0) -> 0 | J13: =IFERROR(VLOOKUP(D13,'Master File - Rate Card'!$B$4:$H$163,5,0),0) -> 0 | K13: =IFERROR(I13/(1-$E$5), 0) -> 0 | L13: =F13*G13*$O$4*H13*I13 -> 0 | M13: =L13/(1-$E$5) -> 0
B14: 6 | E14: =IF(D14="","",TRIM(MID(D14,FIND("|",D14)+1,100))) | I14: =IFERROR(VLOOKUP(D14,'Master File - Rate Card'!$B$4:$H$163,6,0),0) -> 0 | J14: =IFERROR(VLOOKUP(D14,'Master File - Rate Card'!$B$4:$H$163,5,0),0) -> 0 | K14: =IFERROR(I14/(1-$E$5), 0) -> 0 | L14: =F14*G14*$O$4*H14*I14 -> 0 | M14: =L14/(1-$E$5) -> 0
B15: 7 | E15: =IF(D15="","",TRIM(MID(D15,FIND("|",D15)+1,100))) | I15: =IFERROR(VLOOKUP(D15,'Master File - Rate Card'!$B$4:$H$163,6,0),0) -> 0 | J15: =IFERROR(VLOOKUP(D15,'Master File - Rate Card'!$B$4:$H$163,5,0),0) -> 0 | K15: =IFERROR(I15/(1-$E$5), 0) -> 0 | L15: =F15*G15*$O$4*H15*I15 -> 0 | M15: =L15/(1-$E$5) -> 0
B16: 8 | E16: =IF(D16="","",TRIM(MID(D16,FIND("|",D16)+1,100))) | I16: =IFERROR(VLOOKUP(D16,'Master File - Rate Card'!$B$4:$H$163,6,0),0) -> 0 | J16: =IFERROR(VLOOKUP(D16,'Master File - Rate Card'!$B$4:$H$163,5,0),0) -> 0 | K16: =IFERROR(I16/(1-$E$5), 0) -> 0 | L16: =F16*G16*$O$4*H16*I16 -> 0 | M16: =L16/(1-$E$5) -> 0
B17: 9 | E17: =IF(D17="","",TRIM(MID(D17,FIND("|",D17)+1,100))) | I17: =IFERROR(VLOOKUP(D17,'Master File - Rate Card'!$B$4:$H$163,6,0),0) -> 0 | J17: =IFERROR(VLOOKUP(D17,'Master File - Rate Card'!$B$4:$H$163,5,0),0) -> 0 | K17: =IFERROR(I17/(1-$E$5), 0) -> 0 | L17: =F17*G17*$O$4*H17*I17 -> 0 | M17: =L17/(1-$E$5) -> 0
B18: 10 | E18: =IF(D18="","",TRIM(MID(D18,FIND("|",D18)+1,100))) | I18: =IFERROR(VLOOKUP(D18,'Master File - Rate Card'!$B$4:$H$163,6,0),0) -> 0 | J18: =IFERROR(VLOOKUP(D18,'Master File - Rate Card'!$B$4:$H$163,5,0),0) -> 0 | K18: =IFERROR(I18/(1-$E$5), 0) -> 0 | L18: =F18*G18*$O$4*H18*I18 -> 0 | M18: =L18/(1-$E$5) -> 0
B19: 11 | E19: =IF(D19="","",TRIM(MID(D19,FIND("|",D19)+1,100))) | I19: =IFERROR(VLOOKUP(D19,'Master File - Rate Card'!$B$4:$H$163,6,0),0) -> 0 | J19: =IFERROR(VLOOKUP(D19,'Master File - Rate Card'!$B$4:$H$163,5,0),0) -> 0 | K19: =IFERROR(I19/(1-$E$5), 0) -> 0 | L19: =F19*G19*$O$4*H19*I19 -> 0 | M19: =L19/(1-$E$5) -> 0
B20: 12 | E20: =IF(D20="","",TRIM(MID(D20,FIND("|",D20)+1,100))) | I20: =IFERROR(VLOOKUP(D20,'Master File - Rate Card'!$B$4:$H$163,6,0),0) -> 0 | J20: =IFERROR(VLOOKUP(D20,'Master File - Rate Card'!$B$4:$H$163,5,0),0) -> 0 | K20: =IFERROR(I20/(1-$E$5), 0) -> 0 | L20: =F20*G20*$O$4*H20*I20 -> 0 | M20: =L20/(1-$E$5) -> 0
B21: 13 | E21: =IF(D21="","",TRIM(MID(D21,FIND("|",D21)+1,100))) | I21: =IFERROR(VLOOKUP(D21,'Master File - Rate Card'!$B$4:$H$163,6,0),0) -> 0 | J21: =IFERROR(VLOOKUP(D21,'Master File - Rate Card'!$B$4:$H$163,5,0),0) -> 0 | K21: =IFERROR(I21/(1-$E$5), 0) -> 0 | L21: =F21*G21*$O$4*H21*I21 -> 0 | M21: =L21/(1-$E$5) -> 0
... B28: 20 | E28: =IF(D28="","",TRIM(MID(D28,FIND("|",D28)+1,100))) | I28: =IFERROR(VLOOKUP(D28,'Master File - Rate Card'!$B$4:$H$163,6,0),0) -> 0 | J28: =IFERROR(VLOOKUP(D28,'Master File - Rate Card'!$B$4:$H$163,5,0),0) -> 0 | K28: =IFERROR(I28/(1-$E$5), 0) -> 0 | L28: =F28*G28*$O$4*H28*I28 -> 0 | M28: =L28/(1-$E$5) -> 0
B29: PROJECT TOTALS - Onshore | L29: =SUM(L9:L28) -> 3386.875 | M29: =SUM(M9:M28) -> 6773.75
E31: Total Resources: | F31: =SUM(F9:F28) -> 1
E32: =COUNTA(_xlfn.UNIQUE(D9:D28))&" roles configured | Margin: "&TEXT($E$5,"0.0%")&" | Hours/Month: "&$O$4 -> 2 roles configured | Margin: 50.0% | Hours/Month: 160
B33: 📝 HOW TO USE: 1) Select Category (Col B) → Role auto-populates dropdown (Col C) | 2) Enter # People, # Months, Billability % | 3) Rate & Revenue auto-calculate
B34: Blue = User Input | F34: Black = Auto-Calculated | J34: Yellow = Key Assumption

Sheet Revenue & Cost_Offshore 
B2: 💰 OFFSHORE REVENUE & COST CALCULATOR
B4: Project Name: | E4: =Margin_Summary!C3 -> Abc | N4: Hours/Month: | O4: 160
B5: Offshore CM %: | E5: 0.5
B6: Expected GM %: | E6: =IFERROR(IF(Margin_Summary!C4="","",E5*INDEX('Vertical-Based GM Calculation'!$N$2:$N$8,MATCH(Margin_Summary!C4,'Vertical-Based GM Calculation'!$A$2:$A$8,0))),"N/A") -> 0.39840695 | F6: ←Do not change this
B8: # | C8: Category | D8: Role | E8: Experience | F8: # People | G8: # Months | H8: Billability % | I8: Rate $/Hr | J8: Annual CTC ($) | K8: Rate per hour ($) | L8: Total Cost (USD) | M8: Total Revenue (USD) | N8: Notes
B9: 1 | C9: Engineering & Quality | D9: Data Engineer / Data Modeler 1 | 2-3 Years | E9: =IF(D9="","",TRIM(MID(D9,FIND("|",D9)+1,100))) -> 2-3 Years | F9: 1 | G9: 1 | H9: 1 | I9: =IFERROR(VLOOKUP(D9,'Master File - Rate Card'!$B$4:$K$163,10,0),0) -> 7.2804659 | J9: =IFERROR(VLOOKUP(D9,'Master File - Rate Card'!$B$4:$K$163,9,0),0) -> 13589.797 | K9: =IFERROR(I9/(1-$E$5), 0) -> 14.560932 | L9: =F9*G9*$O$4*H9*I9 -> 1164.8746 | M9: =L9/(1-$E$5) -> 2329.7491
B10: 2 | E10: =IF(D10="","",TRIM(MID(D10,FIND("|",D10)+1,100))) | I10: =IFERROR(VLOOKUP(D10,'Master File - Rate Card'!$B$4:$K$163,10,0),0) -> 0 | J10: =IFERROR(VLOOKUP(D10,'Master File - Rate Card'!$B$4:$K$163,9,0),0) -> 0 | K10: =IFERROR(I10/(1-$E$5), 0) -> 0 | L10: =F10*G10*$O$4*H10*I10 -> 0 | M10: =L10/(1-$E$5) -> 0
B11: 3 | E11: =IF(D11="","",TRIM(MID(D11,FIND("|",D11)+1,100))) | I11: =IFERROR(VLOOKUP(D11,'Master File - Rate Card'!$B$4:$K$163,10,0),0) -> 0 | J11: =IFERROR(VLOOKUP(D11,'Master File - Rate Card'!$B$4:$K$163,9,0),0) -> 0 | K11: =IFERROR(I11/(1-$E$5), 0) -> 0 | L11: =F11*G11*$O$4*H11*I11 -> 0 | M11: =L11/(1-$E$5) -> 0
B12: 4 | E12: =IF(D12="","",TRIM(MID(D12,FIND("|",D12)+1,100))) | I12: =IFERROR(VLOOKUP(D12,'Master File - Rate Card'!$B$4:$K$163,10,0),0) -> 0 | J12: =IFERROR(VLOOKUP(D12,'Master File - Rate Card'!$B$4:$K$163,9,0),0) -> 0 | K12: =IFERROR(I12/(1-$E$5), 0) -> 0 | L12: =F12*G12*$O$4*H12*I12 -> 0 | M12: =L12/(1-$E$5) -> 0
B13: 5 | E13: =IF(D13="","",TRIM(MID(D13,FIND("|",D13)+1,100))) | I13: =IFERROR(VLOOKUP(D13,'Master File - Rate Card'!$B$4:$K$163,10,0),0) -> 0 | J13: =IFERROR(VLOOKUP(D13,'Master File - Rate Card'!$B$4:$K$163,9,0),0) -> 0 | K13: =IFERROR(I13/(1-$E$5), 0) -> 0 | L13: =F13*G13*$O$4*H13*I13 -> 0 | M13: =L13/(1-$E$5) -> 0
B14: 6 | E14: =IF(D14="","",TRIM(MID(D14,FIND("|",D14)+1,100))) | I14: =IFERROR(VLOOKUP(D14,'Master File - Rate Card'!$B$4:$K$163,10,0),0) -> 0 | J14: =IFERROR(VLOOKUP(D14,'Master File - Rate Card'!$B$4:$K$163,9,0),0) -> 0 | K14: =IFERROR(I14/(1-$E$5), 0) -> 0 | L14: =F14*G14*$O$4*H14*I14 -> 0 | M14: =L14/(1-$E$5) -> 0
B15: 7 | E15: =IF(D15="","",TRIM(MID(D15,FIND("|",D15)+1,100))) | I15: =IFERROR(VLOOKUP(D15,'Master File - Rate Card'!$B$4:$K$163,10,0),0) -> 0 | J15: =IFERROR(VLOOKUP(D15,'Master File - Rate Card'!$B$4:$K$163,9,0),0) -> 0 | K15: =IFERROR(I15/(1-$E$5), 0) -> 0 | L15: =F15*G15*$O$4*H15*I15 -> 0 | M15: =L15/(1-$E$5) -> 0
B16: 8 | E16: =IF(D16="","",TRIM(MID(D16,FIND("|",D16)+1,100))) | I16: =IFERROR(VLOOKUP(D16,'Master File - Rate Card'!$B$4:$K$163,10,0),0) -> 0 | J16: =IFERROR(VLOOKUP(D16,'Master File - Rate Card'!$B$4:$K$163,9,0),0) -> 0 | K16: =IFERROR(I16/(1-$E$5), 0) -> 0 | L16: =F16*G16*$O$4*H16*I16 -> 0 | M16: =L16/(1-$E$5) -> 0
B17: 9 | E17: =IF(D17="","",TRIM(MID(D17,FIND("|",D17)+1,100))) | I17: =IFERROR(VLOOKUP(D17,'Master File - Rate Card'!$B$4:$K$163,10,0),0) -> 0 | J17: =IFERROR(VLOOKUP(D17,'Master File - Rate Card'!$B$4:$K$163,9,0),0) -> 0 | K17: =IFERROR(I17/(1-$E$5), 0) -> 0 | L17: =F17*G17*$O$4*H17*I17 -> 0 | M17: =L17/(1-$E$5) -> 0
B18: 10 | E18: =IF(D18="","",TRIM(MID(D18,FIND("|",D18)+1,100))) | I18: =IFERROR(VLOOKUP(D18,'Master File - Rate Card'!$B$4:$K$163,10,0),0) -> 0 | J18: =IFERROR(VLOOKUP(D18,'Master File - Rate Card'!$B$4:$K$163,9,0),0) -> 0 | K18: =IFERROR(I18/(1-$E$5), 0) -> 0 | L18: =F18*G18*$O$4*H18*I18 -> 0 | M18: =L18/(1-$E$5) -> 0
B19: 11 | E19: =IF(D19="","",TRIM(MID(D19,FIND("|",D19)+1,100))) | I19: =IFERROR(VLOOKUP(D19,'Master File - Rate Card'!$B$4:$K$163,10,0),0) -> 0 | J19: =IFERROR(VLOOKUP(D19,'Master File - Rate Card'!$B$4:$K$163,9,0),0) -> 0 | K19: =IFERROR(I19/(1-$E$5), 0) -> 0 | L19: =F19*G19*$O$4*H19*I19 -> 0 | M19: =L19/(1-$E$5) -> 0
B20: 12 | E20: =IF(D20="","",TRIM(MID(D20,FIND("|",D20)+1,100))) | I20: =IFERROR(VLOOKUP(D20,'Master File - Rate Card'!$B$4:$K$163,10,0),0) -> 0 | J20: =IFERROR(VLOOKUP(D20,'Master File - Rate Card'!$B$4:$K$163,9,0),0) -> 0 | K20: =IFERROR(I20/(1-$E$5), 0) -> 0 | L20: =F20*G20*$O$4*H20*I20 -> 0 | M20: =L20/(1-$E$5) -> 0
B21: 13 | E21: =IF(D21="","",TRIM(MID(D21,FIND("|",D21)+1,100))) | I21: =IFERROR(VLOOKUP(D21,'Master File - Rate Card'!$B$4:$K$163,10,0),0) -> 0 | J21: =IFERROR(VLOOKUP(D21,'Master File - Rate Card'!$B$4:$K$163,9,0),0) -> 0 | K21: =IFERROR(I21/(1-$E$5), 0) -> 0 | L21: =F21*G21*$O$4*H21*I21 -> 0 | M21: =L21/(1-$E$5) -> 0
... B28: 20 | E28: =IF(D28="","",TRIM(MID(D28,FIND("|",D28)+1,100))) | I28: =IFERROR(VLOOKUP(D28,'Master File - Rate Card'!$B$4:$K$163,10,0),0) -> 0 | J28: =IFERROR(VLOOKUP(D28,'Master File - Rate Card'!$B$4:$K$163,9,0),0) -> 0 | K28: =IFERROR(I28/(1-$E$5), 0) -> 0 | L28: =F28*G28*$O$4*H28*I28 -> 0 | M28: =L28/(1-$E$5) -> 0
B29: PROJECT TOTALS Offshore | L29: =SUM(L9:L28) -> 1164.8746 | M29: =SUM(M9:M28) -> 2329.7491
F31: Total Resources: | G31: =SUM(F9:F28) -> 1
F32: =COUNTA(_xlfn.UNIQUE(D9:D28))&" roles configured | Margin: "&TEXT($E$5,"0.0%")&" | Hours/Month: "&$O$4 -> 2 roles configured | Margin: 50.0% | Hours/Month: 160
B33: 📝 HOW TO USE: 1) Select Category (Col B) → Role auto-populates dropdown (Col C) | 2) Enter # People, # Months, Billability % | 3) Rate, Cost & Revenue auto-calculated
B34: Blue = User Input | F34: Black = Auto-Calculated | J34: Yellow = Key Assumption

Sheet Vertical-Based GM Calculation
A1: Vertical | B1: Total CM (Ref) | C1: Total GM (Ref) | D1: Offshore CM (Ref) | E1: Offshore GM (Ref) | F1: Onshore CM (Ref) | G1: Onshore GM (Ref) | H1: Total GM Ratio | I1: Offshore GM Ratio | J1: Onshore GM Ratio | K1: Offshore GM Ratio | L1: Onshore GM Ratio | M1: Normalized GM Ratio | N1: Normalized Offshore GM Ratio | O1: Normalized Onshore GM Ratio | Q1: Normalization Factor | R1: 0.8
A2: TMT | B2: 0.6873 | C2: 0.5611 | D2: 0.7787 | E2: 0.643 | F2: 0.315 | G2: 0.2271 | H2: =IFERROR(IF(B2="","",C2/B2),"") -> 0.81638295 | I2: =IFERROR(IF(D2="","",E2/D2),"") -> 0.8257352 | J2: =IFERROR(IF(F2="","",G2/F2),"") -> 0.72095238 | K2: =IFERROR(IF(D2="","",E2/D2),"") -> 0.8257352 | L2: =IFERROR(IF(F2="","",G2/F2),"") -> 0.72095238 | M2: =IF(OR($A2="TMT",$A2="RCM"),H2,$R$1) -> 0.81638295 | N2: =IF(OR($A2="TMT",$A2="RCM"),I2,$R$1) -> 0.8257352 | O2: =IF(OR($A2="TMT",$A2="RCM"),J2,$R$1) -> 0.72095238
A3: RAI | B3: 0.8185 | C3: 0.4123 | D3: 0.8185 | E3: 0.4123 | H3: =IFERROR(IF(B3="","",C3/B3),"") -> 0.50372633 | I3: 0.8 | J3: 0.8 | K3: =IFERROR(IF(D3="","",E3/D3),"") -> 0.50372633 | L3: =IFERROR(IF(F3="","",G3/F3),"") | M3: =IF(OR($A3="TMT",$A3="RCM"),H3,$R$1) -> 0.8 | N3: =IF(OR($A3="TMT",$A3="RCM"),I3,$R$1) -> 0.8 | O3: =IF(OR($A3="TMT",$A3="RCM"),J3,$R$1) -> 0.8
A4: RCM | B4: 0.631 | C4: 0.4948 | D4: 0.6905 | E4: 0.5502 | F4: 0.4104 | G4: 0.2893 | H4: =IFERROR(IF(B4="","",C4/B4),"") -> 0.78415214 | I4: =IFERROR(IF(D4="","",E4/D4),"") -> 0.7968139 | J4: =IFERROR(IF(F4="","",G4/F4),"") -> 0.70492203 | K4: =IFERROR(IF(D4="","",E4/D4),"") -> 0.7968139 | L4: =IFERROR(IF(F4="","",G4/F4),"") -> 0.70492203 | M4: =IF(OR($A4="TMT",$A4="RCM"),H4,$R$1) -> 0.78415214 | N4: =IF(OR($A4="TMT",$A4="RCM"),I4,$R$1) -> 0.7968139 | O4: =IF(OR($A4="TMT",$A4="RCM"),J4,$R$1) -> 0.70492203
A5: HLS - CI | B5: 0.7713 | C5: 0.5403 | D5: 0.7713 | E5: 0.5403 | H5: =IFERROR(IF(B5="","",C5/B5),"") -> 0.70050564 | I5: 0.8 | J5: 0.8 | K5: =IFERROR(IF(D5="","",E5/D5),"") -> 0.70050564 | L5: =IFERROR(IF(F5="","",G5/F5),"") | M5: =IF(OR($A5="TMT",$A5="RCM"),H5,$R$1) -> 0.8 | N5: =IF(OR($A5="TMT",$A5="RCM"),I5,$R$1) -> 0.8 | O5: =IF(OR($A5="TMT",$A5="RCM"),J5,$R$1) -> 0.8
A6: ME | B6: 0.5821 | C6: 0.396 | D6: 0.6507 | E6: 0.405 | F6: 0.4649 | G6: 0.3807 | H6: =IFERROR(IF(B6="","",C6/B6),"") -> 0.68029548 | I6: 0.8 | J6: 0.8 | K6: =IFERROR(IF(D6="","",E6/D6),"") -> 0.62240664 | L6: =IFERROR(IF(F6="","",G6/F6),"") -> 0.81888578 | M6: =IF(OR($A6="TMT",$A6="RCM"),H6,$R$1) -> 0.8 | N6: =IF(OR($A6="TMT",$A6="RCM"),I6,$R$1) -> 0.8 | O6: =IF(OR($A6="TMT",$A6="RCM"),J6,$R$1) -> 0.8
A7: Others | B7: 0.6448 | C7: 0.3373 | D7: 0.809 | E7: 0.3883 | F7: 0.3665 | G7: 0.251 | H7: =IFERROR(IF(B7="","",C7/B7),"") -> 0.52310794 | I7: 0.8 | J7: 0.8 | K7: =IFERROR(IF(D7="","",E7/D7),"") -> 0.47997528 | L7: =IFERROR(IF(F7="","",G7/F7),"") -> 0.68485675 | M7: =IF(OR($A7="TMT",$A7="RCM"),H7,$R$1) -> 0.8 | N7: =IF(OR($A7="TMT",$A7="RCM"),I7,$R$1) -> 0.8 | O7: =IF(OR($A7="TMT",$A7="RCM"),J7,$R$1) -> 0.8
A8: HLS - Analytics | B8: 0.7962 | C8: 0.5056 | D8: 0.7262 | E8: 0.4994 | F8: 0.9614 | G8: 0.5201 | H8: =IFERROR(IF(B8="","",C8/B8),"") -> 0.63501633 | I8: 0.8 | J8: 0.8 | K8: =IFERROR(IF(D8="","",E8/D8),"") -> 0.68768934 | L8: =IFERROR(IF(F8="","",G8/F8),"") -> 0.5409819 | M8: =IF(OR($A8="TMT",$A8="RCM"),H8,$R$1) -> 0.8 | N8: =IF(OR($A8="TMT",$A8="RCM"),I8,$R$1) -> 0.8 | O8: =IF(OR($A8="TMT",$A8="RCM"),J8,$R$1) -> 0.8
A9: FY 25-26 Actual Data except column I & J | H9: Actual

Sheet Lists
A1: Categories | B1: Architecture___Design | C1: Engineering___Quality | D1: Data_Science | E1: Program___Project_Management | F1: Professional_Services___Advisory | G1: CI | H1: MI | J1: Verticals | O1: Category | P1: Role_Exp | Q1: Onshore_Rate | R1: Offshore_Rate | S1: Combined_Key | T1: Onshore_Cost/Hr | U1: Offshore_Cost/Hr | AC1: IP
A2: Architecture & Design | B2: Application Architect 1 | 5-10 Years | C2: Cloud Data Engineer 1 | 2-3 Years | D2: AI/ML Engineer (Core AI) | 2–3 Years | E2: Business Analyst 1 | 2-3 Years | F2: Analyst | 2-3 Years | G2: Competitive Intelligence Specialist 1 | 3-5 Years | H2: Market Research Operations 1 | 2-3 Years | J2: TMT | O2: Architecture & Design | P2: Application Architect 1 | 5-10 Years | Q2: =IFERROR(VLOOKUP($P2,'Master File - Rate Card'!$B:$G,6,0),"") -> 95 | R2: =IFERROR(VLOOKUP($P2,'Master File - Rate Card'!$B:$K,10,0),"") -> 20.441308 | S2: Architecture & Design|||Application Architect 1 | 5-10 Years | T2: =Q2 -> 95 | U2: =R2 -> 20.441308 | AC2: Agent5i
A3: Engineering & Quality | B3: Application Architect 2 | 10-15 Years | C3: Cloud Data Engineer 2 | 3-5 Years | D3: AI/ML Engineer (Core AI) | 3–5 Years | E3: Business Analyst 2 | 3-5 Years | F3: Jr. Consultant | 3-5 Years | G3: Competitive Intelligence Specialist 2 | 5-10 Years | H3: Market Research Operations 2 | 3-5 Years | J3: RAI | AC3: BrandTrax
A4: Data Science | B4: Application Architect 3 | 15+ Years | C4: Cloud Data Engineer 3 | 5-10 Years | D4: AI/ML Engineer (Core AI) | 5–7 Years | E4: Business Analyst 3 | 5-10 Years | F4: Consultant | 5-10 Years | H4: Market Research Operations 3 | 5-10 Years | J4: RCM | AC4: Compete
A5: Program & Project Management | B5: BI Architect 1 | 5-10 Years | C5: Cloud Data Engineer 4 | 10-15 Years | D5: AI/ML Engineer (Core AI) | 8–10 Years | E5: Business Analyst 4 | 10-15 Years | F5: Sr. Consultant | 10-15 Years | H5: Market Research Operations 4 | 10-15 Years | J5: HLS - CI | AC5: Discovery
A6: Professional Services & Advisory | B6: BI Architect 2 | 10-15 Years | C6: Cloud Data Engineer 5 | 15+ Years | D6: AI/ML Engineer (Core AI) | 10–15 Years | E6: Business Analyst 5 | 15+ Years | F6: Sr. Consulting Partner | 15+ Years | H6: Primary Researcher 1 | 2-3 Years | J6: ME | AC6: ForeSight
A7: CI | B7: BI Architect 3 | 15+ Years | C7: Data Engineer / Data Modeler 1 | 2-3 Years | D7: AI/ML Architect (Core AI) | 15+ Years | E7: Project Manager 1 | 2-3 Years | H7: Primary Researcher 2 | 3-5 Years | J7: Others | AC7: Incivus
A8: MI | B8: Data Architect 1 | 5-10 Years | C8: Data Engineer / Data Modeler 2 | 3-5 Years | D8: AI Engineer (Generative AI) | 2–3 Years | E8: Project Manager 2 | 3-5 Years | H8: Primary Researcher 3 | 5-10 Years | J8: HLS - Analytics | AC8: MDC
B9: Data Architect 2 | 10-15 Years | C9: Data Engineer / Data Modeler 3 | 5-10 Years | D9: AI Engineer (Generative AI) | 3–5 Years | E9: Project Manager 3 | 5-10 Years | H9: Primary Researcher 4 | 10-15 Years | AC9: Multi-Model
B10: Data Architect 3 | 15+ Years | C10: Data Engineer / Data Modeler 4 | 10-15 Years | D10: AI Engineer (Generative AI) | 5–7 Years | E10: Project Manager 4 | 10-15 Years | H10: Secondary MR / MICI Analyst 1 | 2-3 Years | AC10: Others
B11: Enterprise Architect 1 | 5-10 Years | C11: Data Engineer / Data Modeler 5 | 15+ Years | D11: AI Engineer (Generative AI) | 8–10 Years | E11: Project Manager 5 | 15+ Years | H11: Secondary MR / MICI Analyst 2 | 3-5 Years | AC11: QDesign
B12: Enterprise Architect 2 | 10-15 Years | C12: Database Administrator 1 | 2-3 Years | D12: AI Engineer (Generative AI) | 10–15 Years | E12: Scrum Master 1 | 2-3 Years | H12: Secondary MR / MICI Analyst 3 | 5-10 Years
B13: Enterprise Architect 3 | 15+ Years | C13: Database Administrator 2 | 3-5 Years | D13: AI Architect (Generative AI) | 10–15 Years | E13: Scrum Master 2 | 3-5 Years | H13: Secondary MR / MICI Analyst 4 | 10-15 Years
B14: Information Architect 1 | 5-10 Years | C14: Database Administrator 3 | 5-10 Years | D14: AI Engineer (Agentic AI) | 2–3 Years | E14: Scrum Master 3 | 5-10 Years
B15: Information Architect 2 | 10-15 Years | C15: Database Administrator 4 | 10-15 Years | D15: AI Engineer (Agentic AI) | 3–5 Years | E15: Scrum Master 4 | 10-15 Years
B16: Information Architect 3 | 15+ Years | C16: Database Administrator 5 | 15+ Years | D16: AI Engineer (Agentic AI) | 5–7 Years | E16: Scrum Master 5 | 15+ Years | O16: Architecture & Design | P16: Application Architect 2 | 10-15 Years | Q16: =IFERROR(VLOOKUP($P16,'Master File - Rate Card'!$B:$G,6,0),"") -> 120 | R16: =IFERROR(VLOOKUP($P16,'Master File - Rate Card'!$B:$K,10,0),"") -> 32.202061 | S16: Architecture & Design|||Application Architect 2 | 10-15 Years | T16: =Q16 -> 120 | U16: =R16 -> 32.202061
B17: Solution Architect 1 | 5-10 Years | C17: ETL Developer 1 | 2-3 Years | D17: AI Engineer (Agentic AI) | 8–10 Years | E17: Technical Program Manager 1 | 3-5 Years | O17: Architecture & Design | P17: Application Architect 3 | 15+ Years | Q17: =IFERROR(VLOOKUP($P17,'Master File - Rate Card'!$B:$G,6,0),"") -> 180 | R17: =IFERROR(VLOOKUP($P17,'Master File - Rate Card'!$B:$K,10,0),"") -> 54.603495 | S17: Architecture & Design|||Application Architect 3 | 15+ Years | T17: =Q17 -> 180 | U17: =R17 -> 54.603495
B18: Solution Architect 2 | 10-15 Years | C18: ETL Developer 2 | 3-5 Years | D18: AI Engineer (Agentic AI) | 10–15 Years | E18: Technical Program Manager 2 | 5-10 Years | O18: Architecture & Design | P18: BI Architect 1 | 5-10 Years | Q18: =IFERROR(VLOOKUP($P18,'Master File - Rate Card'!$B:$G,6,0),"") -> 126 | R18: =IFERROR(VLOOKUP($P18,'Master File - Rate Card'!$B:$K,10,0),"") -> 21.001344 | S18: Architecture & Design|||BI Architect 1 | 5-10 Years | T18: =Q18 -> 126 | U18: =R18 -> 21.001344
B19: Solution Architect 3 | 15+ Years | C19: ETL Developer 3 | 5-10 Years | D19: AI Architect (Agentic AI) | 15+ Years | E19: Technical Program Manager 3 | 10-15 Years | O19: Architecture & Design | P19: BI Architect 2 | 10-15 Years | Q19: =IFERROR(VLOOKUP($P19,'Master File - Rate Card'!$B:$G,6,0),"") -> 126 | R19: =IFERROR(VLOOKUP($P19,'Master File - Rate Card'!$B:$K,10,0),"") -> 33.602151 | S19: Architecture & Design|||BI Architect 2 | 10-15 Years | T19: =Q19 -> 126 | U19: =R19 -> 33.602151
C20: ETL Developer 4 | 10-15 Years | D20: AIOps 1 | 2-3 Years | E20: Technical Program Manager 4 | 15+ Years | O20: Architecture & Design | P20: BI Architect 3 | 15+ Years | Q20: =IFERROR(VLOOKUP($P20,'Master File - Rate Card'!$B:$G,6,0),"") -> 126 | R20: =IFERROR(VLOOKUP($P20,'Master File - Rate Card'!$B:$K,10,0),"") -> 46.202957 | S20: Architecture & Design|||BI Architect 3 | 15+ Years | T20: =Q20 -> 126 | U20: =R20 -> 46.202957
C21: ETL Developer 5 | 15+ Years | D21: AIOps 2 | 3-5 Years | O21: Architecture & Design | P21: Data Architect 1 | 5-10 Years | Q21: =IFERROR(VLOOKUP($P21,'Master File - Rate Card'!$B:$G,6,0),"") -> 83.333333 | R21: =IFERROR(VLOOKUP($P21,'Master File - Rate Card'!$B:$K,10,0),"") -> 19.041219 | S21: Architecture & Design|||Data Architect 1 | 5-10 Years | T21: =Q21 -> 83.333333 | U21: =R21 -> 19.041219
C22: Graph Engineer 1 | 2-3 Years | D22: AIOps 3 | 5-10 Years | O22: Architecture & Design | P22: Data Architect 2 | 10-15 Years | Q22: =IFERROR(VLOOKUP($P22,'Master File - Rate Card'!$B:$G,6,0),"") -> 98.958333 | R22: =IFERROR(VLOOKUP($P22,'Master File - Rate Card'!$B:$K,10,0),"") -> 22.96147 | S22: Architecture & Design|||Data Architect 2 | 10-15 Years | T22: =Q22 -> 98.958333 | U22: =R22 -> 22.96147
C23: Graph Engineer 2 | 3-5 Years | D23: AIOps 4 | 10-15 Years | O23: Architecture & Design | P23: Data Architect 3 | 15+ Years | Q23: =IFERROR(VLOOKUP($P23,'Master File - Rate Card'!$B:$G,6,0),"") -> 126 | R23: =IFERROR(VLOOKUP($P23,'Master File - Rate Card'!$B:$K,10,0),"") -> 32.482079 | S23: Architecture & Design|||Data Architect 3 | 15+ Years | T23: =Q23 -> 126 | U23: =R23 -> 32.482079
C24: Graph Engineer 3 | 5-10 Years | D24: AIOps 5 | 15+ Years | O24: Architecture & Design | P24: Enterprise Architect 1 | 5-10 Years | Q24: =IFERROR(VLOOKUP($P24,'Master File - Rate Card'!$B:$G,6,0),"") -> 98.958333 | R24: =IFERROR(VLOOKUP($P24,'Master File - Rate Card'!$B:$K,10,0),"") -> 23.521505 | S24: Architecture & Design|||Enterprise Architect 1 | 5-10 Years | T24: =Q24 -> 98.958333 | U24: =R24 -> 23.521505
C25: Graph Engineer 4 | 10-15 Years | O25: Architecture & Design | P25: Enterprise Architect 2 | 10-15 Years | Q25: =IFERROR(VLOOKUP($P25,'Master File - Rate Card'!$B:$G,6,0),"") -> 125 | R25: =IFERROR(VLOOKUP($P25,'Master File - Rate Card'!$B:$K,10,0),"") -> 26.041667 | S25: Architecture & Design|||Enterprise Architect 2 | 10-15 Years | T25: =Q25 -> 125 | U25: =R25 -> 26.041667
C26: Graph Engineer 5 | 15+ Years | O26: Architecture & Design | P26: Enterprise Architect 3 | 15+ Years | Q26: =IFERROR(VLOOKUP($P26,'Master File - Rate Card'!$B:$G,6,0),"") -> 152 | R26: =IFERROR(VLOOKUP($P26,'Master File - Rate Card'!$B:$K,10,0),"") -> 34.162186 | S26: Architecture & Design|||Enterprise Architect 3 | 15+ Years | T26: =Q26 -> 152 | U26: =R26 -> 34.162186
C27: Backend End Developers 1 | 2-3 Years | O27: Architecture & Design | P27: Information Architect 1 | 5-10 Years | Q27: =IFERROR(VLOOKUP($P27,'Master File - Rate Card'!$B:$G,6,0),"") -> 83.333333 | R27: =IFERROR(VLOOKUP($P27,'Master File - Rate Card'!$B:$K,10,0),"") -> 15.400986 | S27: Architecture & Design|||Information Architect 1 | 5-10 Years | T27: =Q27 -> 83.333333 | U27: =R27 -> 15.400986
C28: Backend End Developers 2 | 3-5 Years | O28: Architecture & Design | P28: Information Architect 2 | 10-15 Years | Q28: =IFERROR(VLOOKUP($P28,'Master File - Rate Card'!$B:$G,6,0),"") -> 98.958333 | R28: =IFERROR(VLOOKUP($P28,'Master File - Rate Card'!$B:$K,10,0),"") -> 22.401434 | S28: Architecture & Design|||Information Architect 2 | 10-15 Years | T28: =Q28 -> 98.958333 | U28: =R28 -> 22.401434
C29: Backend End Developers 3 | 5-10 Years | O29: Architecture & Design | P29: Information Architect 3 | 15+ Years | Q29: =IFERROR(VLOOKUP($P29,'Master File - Rate Card'!$B:$G,6,0),"") -> 126 | R29: =IFERROR(VLOOKUP($P29,'Master File - Rate Card'!$B:$K,10,0),"") -> 29.401882 | S29: Architecture & Design|||Information Architect 3 | 15+ Years | T29: =Q29 -> 126 | U29: =R29 -> 29.401882
C30: Backend End Developers 4 | 10-15 Years | O30: Architecture & Design | P30: Solution Architect 1 | 5-10 Years | Q30: =IFERROR(VLOOKUP($P30,'Master File - Rate Card'!$B:$G,6,0),"") -> 83.333333 | R30: =IFERROR(VLOOKUP($P30,'Master File - Rate Card'!$B:$K,10,0),"") -> 29.401882 | S30: Architecture & Design|||Solution Architect 1 | 5-10 Years | T30: =Q30 -> 83.333333 | U30: =R30 -> 29.401882
C31: BI Developer 1 | 2-3 Years | O31: Architecture & Design | P31: Solution Architect 2 | 10-15 Years | Q31: =IFERROR(VLOOKUP($P31,'Master File - Rate Card'!$B:$G,6,0),"") -> 98.958333 | R31: =IFERROR(VLOOKUP($P31,'Master File - Rate Card'!$B:$K,10,0),"") -> 40.602599 | S31: Architecture & Design|||Solution Architect 2 | 10-15 Years | T31: =Q31 -> 98.958333 | U31: =R31 -> 40.602599
C32: BI Developer 2 | 3-5 Years | O32: Architecture & Design | P32: Solution Architect 3 | 15+ Years | Q32: =IFERROR(VLOOKUP($P32,'Master File - Rate Card'!$B:$G,6,0),"") -> 126 | R32: =IFERROR(VLOOKUP($P32,'Master File - Rate Card'!$B:$K,10,0),"") -> 54.603495 | S32: Architecture & Design|||Solution Architect 3 | 15+ Years | T32: =Q32 -> 126 | U32: =R32 -> 54.603495
C33: BI Developer 3 | 5-10 Years | O33: Engineering & Quality | P33: Cloud Data Engineer 1 | 2-3 Years | Q33: =IFERROR(VLOOKUP($P33,'Master File - Rate Card'!$B:$G,6,0),"") -> 42.335938 | R33: =IFERROR(VLOOKUP($P33,'Master File - Rate Card'!$B:$K,10,0),"") -> 6.1603943 | S33: Engineering & Quality|||Cloud Data Engineer 1 | 2-3 Years | T33: =Q33 -> 42.335938 | U33: =R33 -> 6.1603943
C34: BI Developer 4 | 10-15 Years | O34: Engineering & Quality | P34: Cloud Data Engineer 2 | 3-5 Years | Q34: =IFERROR(VLOOKUP($P34,'Master File - Rate Card'!$B:$G,6,0),"") -> 52.919792 | R34: =IFERROR(VLOOKUP($P34,'Master File - Rate Card'!$B:$K,10,0),"") -> 9.5206093 | S34: Engineering & Quality|||Cloud Data Engineer 2 | 3-5 Years | T34: =Q34 -> 52.919792 | U34: =R34 -> 9.5206093
C35: BI Developer 5 | 15+ Years | O35: Engineering & Quality | P35: Cloud Data Engineer 3 | 5-10 Years | Q35: =IFERROR(VLOOKUP($P35,'Master File - Rate Card'!$B:$G,6,0),"") -> 62 | R35: =IFERROR(VLOOKUP($P35,'Master File - Rate Card'!$B:$K,10,0),"") -> 14.000896 | S35: Engineering & Quality|||Cloud Data Engineer 3 | 5-10 Years | T35: =Q35 -> 62 | U35: =R35 -> 14.000896
C36: Data Analyst 1 | 2-3 Years | O36: Engineering & Quality | P36: Cloud Data Engineer 4 | 10-15 Years | Q36: =IFERROR(VLOOKUP($P36,'Master File - Rate Card'!$B:$G,6,0),"") -> 89 | R36: =IFERROR(VLOOKUP($P36,'Master File - Rate Card'!$B:$K,10,0),"") -> 21.841398 | S36: Engineering & Quality|||Cloud Data Engineer 4 | 10-15 Years | T36: =Q36 -> 89 | U36: =R36 -> 21.841398
... C38: Data Analyst 3 | 5-10 Years | O38: Engineering & Quality | P38: Data Engineer / Data Modeler 1 | 2-3 Years | Q38: =IFERROR(VLOOKUP($P38,'Master File - Rate Card'!$B:$G,6,0),"") -> 42.335938 | R38: =IFERROR(VLOOKUP($P38,'Master File - Rate Card'!$B:$K,10,0),"") -> 7.2804659 | S38: Engineering & Quality|||Data Engineer / Data Modeler 1 | 2-3 Years | T38: =Q38 -> 42.335938 | U38: =R38 -> 7.2804659
C39: Data Analyst 4 | 10-15 Years | O39: =IFERROR(VLOOKUP($M39,'Master File - Rate Card'!$B:$K,10,0),"") | P39: Engineering & Quality|||Data Engineer / Data Modeler 2 | 3-5 Years | Q39: =IFERROR(VLOOKUP($P39,'Master File - Rate Card'!$B:$G,6,0),"") | R39: =IFERROR(VLOOKUP($P39,'Master File - Rate Card'!$B:$K,10,0),"") | T39: =Q39 | U39: =R39
C40: Data Analyst 5 | 15+ Years | O40: =IFERROR(VLOOKUP($M40,'Master File - Rate Card'!$B:$K,10,0),"") | P40: Engineering & Quality|||Data Engineer / Data Modeler 3 | 5-10 Years | Q40: =IFERROR(VLOOKUP($P40,'Master File - Rate Card'!$B:$G,6,0),"") | R40: =IFERROR(VLOOKUP($P40,'Master File - Rate Card'!$B:$K,10,0),"") | T40: =Q40 | U40: =R40
C41: DevOps/DataOps/DevSecOps Engineer 1 | 2-3 Years | O41: =IFERROR(VLOOKUP($M41,'Master File - Rate Card'!$B:$K,10,0),"") | P41: Engineering & Quality|||Data Engineer / Data Modeler 4 | 10-15 Years | Q41: =IFERROR(VLOOKUP($P41,'Master File - Rate Card'!$B:$G,6,0),"") | R41: =IFERROR(VLOOKUP($P41,'Master File - Rate Card'!$B:$K,10,0),"") | T41: =Q41 | U41: =R41
...

Sheet IP_Product Cost
B2: 💡 IP & License Cost Calculator (Placeholder)
B3: Add IP/License costs below. Total Cost and Revenue auto-calculate. Update "Revenue" in row 14 to reflect deal pricing.
B4: Product / License | C4: Phase (Setup / Maintenance) | D4: Module | E4: Cost per Unit ($) | F4: Factor / Qty | G4: Total Cost ($) | H4: Notes
F5: 1 | G5: =IFERROR(E5*F5,"-") -> 0
G6: =IFERROR(E6*F6,"-") -> 0
G7: =IFERROR(E7*F7,"-") -> 0
G8: =IFERROR(E8*F8,"-") -> 0
G9: =IFERROR(E9*F9,"-") -> 0
G10: =IFERROR(E10*F10,"-") -> 0
G11: =IFERROR(E11*F11,"-") -> 0
G12: =IFERROR(E12*F12,"-") -> 0
G13: =IFERROR(E13*F13,"-") -> 0
B15: TOTAL IP COST | G15: =SUM(G5:G13) -> 0
B16: REVENUE (from deal) | H16: ← Enter deal revenue for IP/License
B17: IP MARGIN (%) | G17: =IFERROR((G16-G15)/G16, "-") -> -

Sheet Master File - Rate Card
A1: Current Dollar | B1: {=_FV(D1,"Price")} -> 95.66 | D1: #VALUE! | F1: OnShore Employee | H1: Offshore Employee
F2: CTC | H2: CTC
A3: Category | B3: Role - Exp | C3: Role | D3: Experience (Yrs) | E3: Description | F3: CTC (pa) | G3: cost per hour | H3: CTC (INR) | I3: Cost per hour (Rs) | J3: CTC (dollar) | K3: Rate per hour (Rs) | L3: Approvers
A4: Architecture & Design | B4: =CONCATENATE(C4, " | ",D4) -> Application Architect 1 | 5-10 Years | C4: Application Architect 1 | D4: 5-10 Years | E4: - | F4: 182400 | G4: =F4/1920 -> 95 | H4: 3650000 | I4: =H4/1920 -> 1901.0417 | J4: =H4/$B$1 -> 38155.969 | K4: =I4/93 -> 20.441308 | L4: Namratta
A5: Architecture & Design | B5: =CONCATENATE(C5, " | ",D5) -> Application Architect 2 | 10-15 Years | C5: Application Architect 2 | D5: 10-15 Years | E5: - | F5: 230400 | G5: =F5/1920 -> 120 | H5: 5750000 | I5: =H5/1920 -> 2994.7917 | J5: =H5/$B$1 -> 60108.718 | K5: =I5/93 -> 32.202061 | L5: Namratta
A6: Architecture & Design | B6: =CONCATENATE(C6, " | ",D6) -> Application Architect 3 | 15+ Years | C6: Application Architect 3 | D6: 15+ Years | E6: - | F6: 345600 | G6: =F6/1920 -> 180 | H6: 9750000 | I6: =H6/1920 -> 5078.125 | J6: =H6/$B$1 -> 101923.48 | K6: =I6/93 -> 54.603495 | L6: Namratta
A7: Architecture & Design | B7: =CONCATENATE(C7, " | ",D7) -> BI Architect 1 | 5-10 Years | C7: BI Architect 1 | D7: 5-10 Years | E7: - | F7: 241920 | G7: =F7/1920 -> 126 | H7: 3750000 | I7: =H7/1920 -> 1953.125 | J7: =H7/$B$1 -> 39201.338 | K7: =I7/93 -> 21.001344 | L7: Namratta
A8: Architecture & Design | B8: =CONCATENATE(C8, " | ",D8) -> BI Architect 2 | 10-15 Years | C8: BI Architect 2 | D8: 10-15 Years | E8: - | F8: 241920 | G8: =F8/1920 -> 126 | H8: 6000000 | I8: =H8/1920 -> 3125 | J8: =H8/$B$1 -> 62722.141 | K8: =I8/93 -> 33.602151 | L8: Namratta
A9: Architecture & Design | B9: =CONCATENATE(C9, " | ",D9) -> BI Architect 3 | 15+ Years | C9: BI Architect 3 | D9: 15+ Years | E9: - | F9: 241920 | G9: =F9/1920 -> 126 | H9: 8250000 | I9: =H9/1920 -> 4296.875 | J9: =H9/$B$1 -> 86242.944 | K9: =I9/93 -> 46.202957 | L9: Namratta
A10: Architecture & Design | B10: =CONCATENATE(C10, " | ",D10) -> Data Architect 1 | 5-10 Years | C10: Data Architect 1 | D10: 5-10 Years | E10: - | F10: 160000 | G10: =F10/1920 -> 83.333333 | H10: 3400000 | I10: =H10/1920 -> 1770.8333 | J10: =H10/B1 -> 35542.547 | K10: =I10/93 -> 19.041219 | L10: Rakesh
A11: Architecture & Design | B11: =CONCATENATE(C11, " | ",D11) -> Data Architect 2 | 10-15 Years | C11: Data Architect 2 | D11: 10-15 Years | E11: - | F11: 190000 | G11: =F11/1920 -> 98.958333 | H11: 4100000 | I11: =H11/1920 -> 2135.4167 | J11: =H11/B1 -> 42860.13 | K11: =I11/93 -> 22.96147 | L11: Rakesh
A12: Architecture & Design | B12: =CONCATENATE(C12, " | ",D12) -> Data Architect 3 | 15+ Years | C12: Data Architect 3 | D12: 15+ Years | E12: - | F12: 241920 | G12: =F12/1920 -> 126 | H12: 5800000 | I12: =H12/1920 -> 3020.8333 | J12: =H12/B1 -> 60631.403 | K12: =I12/93 -> 32.482079 | L12: Rakesh
A13: Architecture & Design | B13: =CONCATENATE(C13, " | ",D13) -> Enterprise Architect 1 | 5-10 Years | C13: Enterprise Architect 1 | D13: 5-10 Years | E13: - | F13: 190000 | G13: =F13/1920 -> 98.958333 | H13: 4200000 | I13: =H13/1920 -> 2187.5 | J13: =H13/B1 -> 43905.499 | K13: =I13/93 -> 23.521505 | L13: Rakesh
A14: Architecture & Design | B14: =CONCATENATE(C14, " | ",D14) -> Enterprise Architect 2 | 10-15 Years | C14: Enterprise Architect 2 | D14: 10-15 Years | E14: - | F14: 240000 | G14: =F14/1920 -> 125 | H14: 4650000 | I14: =H14/1920 -> 2421.875 | J14: =H14/B1 -> 48609.659 | K14: =I14/93 -> 26.041667 | L14: Rakesh
A15: Architecture & Design | B15: =CONCATENATE(C15, " | ",D15) -> Enterprise Architect 3 | 15+ Years | C15: Enterprise Architect 3 | D15: 15+ Years | E15: - | F15: 291840 | G15: =F15/1920 -> 152 | H15: 6100000 | I15: =H15/1920 -> 3177.0833 | J15: =H15/B1 -> 63767.51 | K15: =I15/93 -> 34.162186 | L15: Rakesh
A16: Architecture & Design | B16: =CONCATENATE(C16, " | ",D16) -> Information Architect 1 | 5-10 Years | C16: Information Architect 1 | D16: 5-10 Years | E16: - | F16: 160000 | G16: =F16/1920 -> 83.333333 | H16: 2750000 | I16: =H16/1920 -> 1432.2917 | J16: =H16/B1 -> 28747.648 | K16: =I16/93 -> 15.400986 | L16: Rakesh
A17: Architecture & Design | B17: =CONCATENATE(C17, " | ",D17) -> Information Architect 2 | 10-15 Years | C17: Information Architect 2 | D17: 10-15 Years | E17: - | F17: 190000 | G17: =F17/1920 -> 98.958333 | H17: 4000000 | I17: =H17/1920 -> 2083.3333 | J17: =H17/B1 -> 41814.761 | K17: =I17/93 -> 22.401434 | L17: Rakesh
A18: Architecture & Design | B18: =CONCATENATE(C18, " | ",D18) -> Information Architect 3 | 15+ Years | C18: Information Architect 3 | D18: 15+ Years | E18: - | F18: 241920 | G18: =F18/1920 -> 126 | H18: 5250000 | I18: =H18/1920 -> 2734.375 | J18: =H18/B1 -> 54881.873 | K18: =I18/93 -> 29.401882 | L18: Rakesh
A19: Architecture & Design | B19: =CONCATENATE(C19, " | ",D19) -> Solution Architect 1 | 5-10 Years | C19: Solution Architect 1 | D19: 5-10 Years | E19: - | F19: 160000 | G19: =F19/1920 -> 83.333333 | H19: 5250000 | I19: =H19/1920 -> 2734.375 | J19: =H19/B1 -> 54881.873 | K19: =I19/93 -> 29.401882 | L19: Rakesh
A20: Architecture & Design | B20: =CONCATENATE(C20, " | ",D20) -> Solution Architect 2 | 10-15 Years | C20: Solution Architect 2 | D20: 10-15 Years | E20: - | F20: 190000 | G20: =F20/1920 -> 98.958333 | H20: 7250000 | I20: =H20/1920 -> 3776.0417 | J20: =H20/B1 -> 75789.254 | K20: =I20/93 -> 40.602599 | L20: Rakesh
A21: Architecture & Design | B21: =CONCATENATE(C21, " | ",D21) -> Solution Architect 3 | 15+ Years | C21: Solution Architect 3 | D21: 15+ Years | E21: - | F21: 241920 | G21: =F21/1920 -> 126 | H21: 9750000 | I21: =H21/1920 -> 5078.125 | J21: =H21/B1 -> 101923.48 | K21: =I21/93 -> 54.603495 | L21: Rakesh
A22: Engineering & Quality | B22: =CONCATENATE(C22, " | ",D22) -> Cloud Data Engineer 1 | 2-3 Years | C22: Cloud Data Engineer 1 | D22: 2-3 Years | E22: - | F22: 81285 | G22: =F22/1920 -> 42.335938 | H22: 1100000 | I22: =H22/1920 -> 572.91667 | J22: =H22/B1 -> 11499.059 | K22: =I22/93 -> 6.1603943 | L22: Rakesh
A23: Engineering & Quality | B23: =CONCATENATE(C23, " | ",D23) -> Cloud Data Engineer 2 | 3-5 Years | C23: Cloud Data Engineer 2 | D23: 3-5 Years | E23: - | F23: 101606 | G23: =F23/1920 -> 52.919792 | H23: 1700000 | I23: =H23/1920 -> 885.41667 | J23: =H23/B1 -> 17771.273 | K23: =I23/93 -> 9.5206093 | L23: Rakesh
A24: Engineering & Quality | B24: =CONCATENATE(C24, " | ",D24) -> Cloud Data Engineer 3 | 5-10 Years | C24: Cloud Data Engineer 3 | D24: 5-10 Years | E24: - | F24: 119040 | G24: =F24/1920 -> 62 | H24: 2500000 | I24: =H24/1920 -> 1302.0833 | J24: =H24/B1 -> 26134.225 | K24: =I24/93 -> 14.000896 | L24: Rakesh
A25: Engineering & Quality | B25: =CONCATENATE(C25, " | ",D25) -> Cloud Data Engineer 4 | 10-15 Years | C25: Cloud Data Engineer 4 | D25: 10-15 Years | E25: - | F25: 170880 | G25: =F25/1920 -> 89 | H25: 3900000 | I25: =H25/1920 -> 2031.25 | J25: =H25/B1 -> 40769.392 | K25: =I25/93 -> 21.841398 | L25: Rakesh
A26: Engineering & Quality | B26: =CONCATENATE(C26, " | ",D26) -> Cloud Data Engineer 5 | 15+ Years | C26: Cloud Data Engineer 5 | D26: 15+ Years | E26: - | F26: 224640 | G26: =F26/1920 -> 117 | H26: 5250000 | I26: =H26/1920 -> 2734.375 | J26: =H26/B1 -> 54881.873 | K26: =I26/93 -> 29.401882 | L26: Rakesh
A27: Engineering & Quality | B27: =CONCATENATE(C27, " | ",D27) -> Data Engineer / Data Modeler 1 | 2-3 Years | C27: Data Engineer / Data Modeler 1 | D27: 2-3 Years | E27: - | F27: 81285 | G27: =F27/1920 -> 42.335938 | H27: 1300000 | I27: =H27/1920 -> 677.08333 | J27: =H27/B1 -> 13589.797 | K27: =I27/93 -> 7.2804659 | L27: Rakesh
A28: Engineering & Quality | B28: =CONCATENATE(C28, " | ",D28) -> Data Engineer / Data Modeler 2 | 3-5 Years | C28: Data Engineer / Data Modeler 2 | D28: 3-5 Years | E28: - | F28: 104509 | G28: =F28/1920 -> 54.431771 | H28: 1700000 | I28: =H28/1920 -> 885.41667 | J28: =H28/B1 -> 17771.273 | K28: =I28/93 -> 9.5206093 | L28: Rakesh
A29: Engineering & Quality | B29: =CONCATENATE(C29, " | ",D29) -> Data Engineer / Data Modeler 3 | 5-10 Years | C29: Data Engineer / Data Modeler 3 | D29: 5-10 Years | E29: - | F29: 144000 | G29: =F29/1920 -> 75 | H29: 2600000 | I29: =H29/1920 -> 1354.1667 | J29: =H29/B1 -> 27179.594 | K29: =I29/93 -> 14.560932 | L29: Rakesh
A30: Engineering & Quality | B30: =CONCATENATE(C30, " | ",D30) -> Data Engineer / Data Modeler 4 | 10-15 Years | C30: Data Engineer / Data Modeler 4 | D30: 10-15 Years | E30: - | F30: 197760 | G30: =F30/1920 -> 103 | H30: 4100000 | I30: =H30/1920 -> 2135.4167 | J30: =H30/B1 -> 42860.13 | K30: =I30/93 -> 22.96147 | L30: Rakesh
A31: Engineering & Quality | B31: =CONCATENATE(C31, " | ",D31) -> Data Engineer / Data Modeler 5 | 15+ Years | C31: Data Engineer / Data Modeler 5 | D31: 15+ Years | E31: - | F31: 251520 | G31: =F31/1920 -> 131 | H31: 5600000 | I31: =H31/1920 -> 2916.6667 | J31: =H31/B1 -> 58540.665 | K31: =I31/93 -> 31.362007 | L31: Rakesh
A32: Engineering & Quality | B32: =CONCATENATE(C32, " | ",D32) -> Database Administrator 1 | 2-3 Years | C32: Database Administrator 1 | D32: 2-3 Years | E32: - | F32: 81285.12 | G32: =F32/1920 -> 42.336 | H32: 1100000 | I32: =H32/1920 -> 572.91667 | J32: =H32/B1 -> 11499.059 | K32: =I32/93 -> 6.1603943 | L32: Rakesh
A33: Engineering & Quality | B33: =CONCATENATE(C33, " | ",D33) -> Database Administrator 2 | 3-5 Years | C33: Database Administrator 2 | D33: 3-5 Years | E33: - | F33: 95800.32 | G33: =F33/1920 -> 49.896 | H33: 1750000 | I33: =H33/1920 -> 911.45833 | J33: =H33/B1 -> 18293.958 | K33: =I33/93 -> 9.8006272 | L33: Rakesh
A34: Engineering & Quality | B34: =CONCATENATE(C34, " | ",D34) -> Database Administrator 3 | 5-10 Years | C34: Database Administrator 3 | D34: 5-10 Years | E34: - | F34: 144000 | G34: =F34/1920 -> 75 | H34: 2250000 | I34: =H34/1920 -> 1171.875 | J34: =H34/B1 -> 23520.803 | K34: =I34/93 -> 12.600806 | L34: Rakesh
A35: Engineering & Quality | B35: =CONCATENATE(C35, " | ",D35) -> Database Administrator 4 | 10-15 Years | C35: Database Administrator 4 | D35: 10-15 Years | E35: - | F35: 197760 | G35: =F35/1920 -> 103 | H35: 3100000 | I35: =H35/1920 -> 1614.5833 | J35: =H35/B1 -> 32406.439 | K35: =I35/93 -> 17.361111 | L35: Rakesh
A36: Engineering & Quality | B36: =CONCATENATE(C36, " | ",D36) -> Database Administrator 5 | 15+ Years | C36: Database Administrator 5 | D36: 15+ Years | E36: - | F36: 251520 | G36: =F36/1920 -> 131 | H36: 4600000 | I36: =H36/1920 -> 2395.8333 | J36: =H36/B1 -> 48086.975 | K36: =I36/93 -> 25.761649 | L36: Rakesh
A37: Engineering & Quality | B37: =CONCATENATE(C37, " | ",D37) -> ETL Developer 1 | 2-3 Years | C37: ETL Developer 1 | D37: 2-3 Years | E37: - | F37: 66770 | G37: =F37/1920 -> 34.776042 | H37: 900000 | I37: =H37/1920 -> 468.75 | J37: =H37/B1 -> 9408.3211 | K37: =I37/93 -> 5.0403226 | L37: Rakesh
A38: Engineering & Quality | B38: =CONCATENATE(C38, " | ",D38) -> ETL Developer 2 | 3-5 Years | C38: ETL Developer 2 | D38: 3-5 Years | E38: - | F38: 92188 | G38: =F38/1920 -> 48.014583 | H38: 1550000 | I38: =H38/1920 -> 807.29167 | J38: =H38/B1 -> 16203.22 | K38: =I38/93 -> 8.6805556 | L38: Rakesh
A39: Engineering & Quality | B39: =CONCATENATE(C39, " | ",D39) -> ETL Developer 3 | 5-10 Years | C39: ETL Developer 3 | D39: 5-10 Years | E39: - | F39: 120360 | G39: =F39/1920 -> 62.6875 | H39: 2250000 | I39: =H39/1920 -> 1171.875 | J39: =H39/B1 -> 23520.803 | K39: =I39/93 -> 12.600806 | L39: Rakesh
A40: Engineering & Quality | B40: =CONCATENATE(C40, " | ",D40) -> ETL Developer 4 | 10-15 Years | C40: ETL Developer 4 | D40: 10-15 Years | E40: - | F40: 145640 | G40: =F40/1920 -> 75.854167 | H40: 3600000 | I40: =H40/1920 -> 1875 | J40: =H40/B1 -> 37633.285 | K40: =I40/93 -> 20.16129 | L40: Rakesh
...
